{
  "nbformat": 4,
  "nbformat_minor": 0,
  "metadata": {
    "colab": {
      "provenance": []
    },
    "kernelspec": {
      "name": "python3",
      "display_name": "Python 3"
    },
    "language_info": {
      "name": "python"
    }
  },
  "cells": [
    {
      "cell_type": "code",
      "source": [
        "import cv2\n",
        "\n",
        "def motion_analysis(video_path):\n",
        "    cap = cv2.VideoCapture(video_path)\n",
        "    ret, prev_frame = cap.read()\n",
        "    prev_gray = cv2.cvtColor(prev_frame, cv2.COLOR_BGR2GRAY)\n",
        "\n",
        "    while cap.isOpened():\n",
        "        ret, frame = cap.read()\n",
        "        if not ret:\n",
        "            break\n",
        "\n",
        "        gray = cv2.cvtColor(frame, cv2.COLOR_BGR2GRAY)\n",
        "\n",
        "        edges_prev = cv2.Canny(prev_gray, 50, 150)\n",
        "        edges_curr = cv2.Canny(gray, 50, 150)\n",
        "\n",
        "        frame_diff = cv2.absdiff(edges_prev, edges_curr)\n",
        "\n",
        "        cv2.imshow('Moving Edges', frame_diff)\n",
        "\n",
        "        if cv2.waitKey(30) & 0xFF == ord('q'):\n",
        "            break\n",
        "\n",
        "        prev_gray = gray.copy()\n",
        "\n",
        "    cap.release()\n",
        "    cv2.destroyAllWindows()\n",
        "\n",
        "# Replace 'path_to_video.mp4' with your video file path\n",
        "video_path = \"background-video-people-walking-1080-ytshorts.savetube.me.mp4\"\n",
        "motion_analysis(video_path)\n"
      ],
      "metadata": {
        "colab": {
          "base_uri": "https://localhost:8080/",
          "height": 418
        },
        "id": "RnQyAjxiD9Rj",
        "outputId": "2d05d3e8-b2e4-409d-ee22-3b59c9720a4c"
      },
      "execution_count": 20,
      "outputs": [
        {
          "output_type": "error",
          "ename": "DisabledFunctionError",
          "evalue": "cv2.imshow() is disabled in Colab, because it causes Jupyter sessions\nto crash; see https://github.com/jupyter/notebook/issues/3935.\nAs a substitution, consider using\n  from google.colab.patches import cv2_imshow\n",
          "traceback": [
            "\u001b[0;31m---------------------------------------------------------------------------\u001b[0m",
            "\u001b[0;31mDisabledFunctionError\u001b[0m                     Traceback (most recent call last)",
            "\u001b[0;32m<ipython-input-20-d8607e3abc04>\u001b[0m in \u001b[0;36m<cell line: 5>\u001b[0;34m()\u001b[0m\n\u001b[1;32m     15\u001b[0m             \u001b[0mx\u001b[0m\u001b[0;34m,\u001b[0m \u001b[0my\u001b[0m\u001b[0;34m,\u001b[0m \u001b[0mw\u001b[0m\u001b[0;34m,\u001b[0m \u001b[0mh\u001b[0m \u001b[0;34m=\u001b[0m \u001b[0mcv2\u001b[0m\u001b[0;34m.\u001b[0m\u001b[0mboundingRect\u001b[0m\u001b[0;34m(\u001b[0m\u001b[0mcontour\u001b[0m\u001b[0;34m)\u001b[0m\u001b[0;34m\u001b[0m\u001b[0;34m\u001b[0m\u001b[0m\n\u001b[1;32m     16\u001b[0m             \u001b[0mcv2\u001b[0m\u001b[0;34m.\u001b[0m\u001b[0mrectangle\u001b[0m\u001b[0;34m(\u001b[0m\u001b[0mframe\u001b[0m\u001b[0;34m,\u001b[0m \u001b[0;34m(\u001b[0m\u001b[0mx\u001b[0m\u001b[0;34m,\u001b[0m \u001b[0my\u001b[0m\u001b[0;34m)\u001b[0m\u001b[0;34m,\u001b[0m \u001b[0;34m(\u001b[0m\u001b[0mx\u001b[0m \u001b[0;34m+\u001b[0m \u001b[0mw\u001b[0m\u001b[0;34m,\u001b[0m \u001b[0my\u001b[0m \u001b[0;34m+\u001b[0m \u001b[0mh\u001b[0m\u001b[0;34m)\u001b[0m\u001b[0;34m,\u001b[0m \u001b[0;34m(\u001b[0m\u001b[0;36m0\u001b[0m\u001b[0;34m,\u001b[0m \u001b[0;36m255\u001b[0m\u001b[0;34m,\u001b[0m \u001b[0;36m0\u001b[0m\u001b[0;34m)\u001b[0m\u001b[0;34m,\u001b[0m \u001b[0;36m2\u001b[0m\u001b[0;34m)\u001b[0m\u001b[0;34m\u001b[0m\u001b[0;34m\u001b[0m\u001b[0m\n\u001b[0;32m---> 17\u001b[0;31m     \u001b[0mcv2\u001b[0m\u001b[0;34m.\u001b[0m\u001b[0mimshow\u001b[0m\u001b[0;34m(\u001b[0m\u001b[0;34m'Video'\u001b[0m\u001b[0;34m,\u001b[0m \u001b[0mframe\u001b[0m\u001b[0;34m)\u001b[0m\u001b[0;34m\u001b[0m\u001b[0;34m\u001b[0m\u001b[0m\n\u001b[0m\u001b[1;32m     18\u001b[0m \u001b[0;34m\u001b[0m\u001b[0m\n\u001b[1;32m     19\u001b[0m     \u001b[0;32mif\u001b[0m \u001b[0mcv2\u001b[0m\u001b[0;34m.\u001b[0m\u001b[0mwaitKey\u001b[0m\u001b[0;34m(\u001b[0m\u001b[0;36m1\u001b[0m\u001b[0;34m)\u001b[0m \u001b[0;34m&\u001b[0m \u001b[0;36m0xFF\u001b[0m \u001b[0;34m==\u001b[0m \u001b[0mord\u001b[0m\u001b[0;34m(\u001b[0m\u001b[0;34m'q'\u001b[0m\u001b[0;34m)\u001b[0m\u001b[0;34m:\u001b[0m\u001b[0;34m\u001b[0m\u001b[0;34m\u001b[0m\u001b[0m\n",
            "\u001b[0;32m/usr/local/lib/python3.10/dist-packages/google/colab/_import_hooks/_cv2.py\u001b[0m in \u001b[0;36mwrapped\u001b[0;34m(*args, **kwargs)\u001b[0m\n\u001b[1;32m     46\u001b[0m   \u001b[0;32mdef\u001b[0m \u001b[0mwrapped\u001b[0m\u001b[0;34m(\u001b[0m\u001b[0;34m*\u001b[0m\u001b[0margs\u001b[0m\u001b[0;34m,\u001b[0m \u001b[0;34m**\u001b[0m\u001b[0mkwargs\u001b[0m\u001b[0;34m)\u001b[0m\u001b[0;34m:\u001b[0m\u001b[0;34m\u001b[0m\u001b[0;34m\u001b[0m\u001b[0m\n\u001b[1;32m     47\u001b[0m     \u001b[0;32mif\u001b[0m \u001b[0;32mnot\u001b[0m \u001b[0mos\u001b[0m\u001b[0;34m.\u001b[0m\u001b[0menviron\u001b[0m\u001b[0;34m.\u001b[0m\u001b[0mget\u001b[0m\u001b[0;34m(\u001b[0m\u001b[0menv_var\u001b[0m\u001b[0;34m,\u001b[0m \u001b[0;32mFalse\u001b[0m\u001b[0;34m)\u001b[0m\u001b[0;34m:\u001b[0m\u001b[0;34m\u001b[0m\u001b[0;34m\u001b[0m\u001b[0m\n\u001b[0;32m---> 48\u001b[0;31m       \u001b[0;32mraise\u001b[0m \u001b[0mDisabledFunctionError\u001b[0m\u001b[0;34m(\u001b[0m\u001b[0mmessage\u001b[0m\u001b[0;34m,\u001b[0m \u001b[0mname\u001b[0m \u001b[0;32mor\u001b[0m \u001b[0mfunc\u001b[0m\u001b[0;34m.\u001b[0m\u001b[0m__name__\u001b[0m\u001b[0;34m)\u001b[0m\u001b[0;34m\u001b[0m\u001b[0;34m\u001b[0m\u001b[0m\n\u001b[0m\u001b[1;32m     49\u001b[0m     \u001b[0;32mreturn\u001b[0m \u001b[0mfunc\u001b[0m\u001b[0;34m(\u001b[0m\u001b[0;34m*\u001b[0m\u001b[0margs\u001b[0m\u001b[0;34m,\u001b[0m \u001b[0;34m**\u001b[0m\u001b[0mkwargs\u001b[0m\u001b[0;34m)\u001b[0m\u001b[0;34m\u001b[0m\u001b[0;34m\u001b[0m\u001b[0m\n\u001b[1;32m     50\u001b[0m \u001b[0;34m\u001b[0m\u001b[0m\n",
            "\u001b[0;31mDisabledFunctionError\u001b[0m: cv2.imshow() is disabled in Colab, because it causes Jupyter sessions\nto crash; see https://github.com/jupyter/notebook/issues/3935.\nAs a substitution, consider using\n  from google.colab.patches import cv2_imshow\n"
          ],
          "errorDetails": {
            "actions": [
              {
                "action": "open_snippet",
                "actionText": "Search Snippets for cv2.imshow",
                "snippetFilter": "cv2.imshow"
              }
            ]
          }
        }
      ]
    },
    {
      "cell_type": "code",
      "source": [],
      "metadata": {
        "colab": {
          "base_uri": "https://localhost:8080/"
        },
        "id": "MZLtqAGuNVXE",
        "outputId": "91d3e87a-fb33-4a7a-db46-7e911be2eb5c"
      },
      "execution_count": 16,
      "outputs": [
        {
          "output_type": "stream",
          "name": "stdout",
          "text": [
            "Collecting face_recognition\n",
            "  Downloading face_recognition-1.3.0-py2.py3-none-any.whl (15 kB)\n",
            "Collecting face-recognition-models>=0.3.0 (from face_recognition)\n",
            "  Downloading face_recognition_models-0.3.0.tar.gz (100.1 MB)\n",
            "\u001b[2K     \u001b[90m━━━━━━━━━━━━━━━━━━━━━━━━━━━━━━━━━━━━━━━━\u001b[0m \u001b[32m100.1/100.1 MB\u001b[0m \u001b[31m8.1 MB/s\u001b[0m eta \u001b[36m0:00:00\u001b[0m\n",
            "\u001b[?25h  Preparing metadata (setup.py) ... \u001b[?25l\u001b[?25hdone\n",
            "Requirement already satisfied: Click>=6.0 in /usr/local/lib/python3.10/dist-packages (from face_recognition) (8.1.7)\n",
            "Requirement already satisfied: dlib>=19.7 in /usr/local/lib/python3.10/dist-packages (from face_recognition) (19.24.4)\n",
            "Requirement already satisfied: numpy in /usr/local/lib/python3.10/dist-packages (from face_recognition) (1.25.2)\n",
            "Requirement already satisfied: Pillow in /usr/local/lib/python3.10/dist-packages (from face_recognition) (9.4.0)\n",
            "Building wheels for collected packages: face-recognition-models\n",
            "  Building wheel for face-recognition-models (setup.py) ... \u001b[?25l\u001b[?25hdone\n",
            "  Created wheel for face-recognition-models: filename=face_recognition_models-0.3.0-py2.py3-none-any.whl size=100566170 sha256=6b46bc9229f63e132f098b25e3e97869d8d8b8d9e01ab90efc0c462194b3ee56\n",
            "  Stored in directory: /root/.cache/pip/wheels/7a/eb/cf/e9eced74122b679557f597bb7c8e4c739cfcac526db1fd523d\n",
            "Successfully built face-recognition-models\n",
            "Installing collected packages: face-recognition-models, face_recognition\n",
            "Successfully installed face-recognition-models-0.3.0 face_recognition-1.3.0\n"
          ]
        }
      ]
    },
    {
      "cell_type": "code",
      "source": [],
      "metadata": {
        "colab": {
          "base_uri": "https://localhost:8080/",
          "height": 391
        },
        "id": "_UJIBZ2dDA_X",
        "outputId": "06e0fdb1-3a2b-4a12-8145-6beffb6fe61c"
      },
      "execution_count": 17,
      "outputs": [
        {
          "output_type": "error",
          "ename": "RuntimeError",
          "evalue": "Error while calling cudaGetDevice(&the_device_id) in file /tmp/pip-install-bl_f6nbt/dlib_b7e3f77affac4712b41e4d328d8f290d/dlib/cuda/gpu_data.cpp:204. code: 35, reason: CUDA driver version is insufficient for CUDA runtime version",
          "traceback": [
            "\u001b[0;31m---------------------------------------------------------------------------\u001b[0m",
            "\u001b[0;31mRuntimeError\u001b[0m                              Traceback (most recent call last)",
            "\u001b[0;32m<ipython-input-17-c44a2d45c82d>\u001b[0m in \u001b[0;36m<cell line: 1>\u001b[0;34m()\u001b[0m\n\u001b[0;32m----> 1\u001b[0;31m \u001b[0;32mimport\u001b[0m \u001b[0mface_recognition\u001b[0m\u001b[0;34m\u001b[0m\u001b[0;34m\u001b[0m\u001b[0m\n\u001b[0m\u001b[1;32m      2\u001b[0m \u001b[0;32mimport\u001b[0m \u001b[0mpickle\u001b[0m\u001b[0;34m\u001b[0m\u001b[0;34m\u001b[0m\u001b[0m\n\u001b[1;32m      3\u001b[0m \u001b[0;32mimport\u001b[0m \u001b[0mcv2\u001b[0m\u001b[0;34m\u001b[0m\u001b[0;34m\u001b[0m\u001b[0m\n\u001b[1;32m      4\u001b[0m \u001b[0;32mimport\u001b[0m \u001b[0mos\u001b[0m\u001b[0;34m\u001b[0m\u001b[0;34m\u001b[0m\u001b[0m\n\u001b[1;32m      5\u001b[0m \u001b[0;34m\u001b[0m\u001b[0m\n",
            "\u001b[0;32m/usr/local/lib/python3.10/dist-packages/face_recognition/__init__.py\u001b[0m in \u001b[0;36m<module>\u001b[0;34m\u001b[0m\n\u001b[1;32m      5\u001b[0m \u001b[0m__version__\u001b[0m \u001b[0;34m=\u001b[0m \u001b[0;34m'1.2.3'\u001b[0m\u001b[0;34m\u001b[0m\u001b[0;34m\u001b[0m\u001b[0m\n\u001b[1;32m      6\u001b[0m \u001b[0;34m\u001b[0m\u001b[0m\n\u001b[0;32m----> 7\u001b[0;31m \u001b[0;32mfrom\u001b[0m \u001b[0;34m.\u001b[0m\u001b[0mapi\u001b[0m \u001b[0;32mimport\u001b[0m \u001b[0mload_image_file\u001b[0m\u001b[0;34m,\u001b[0m \u001b[0mface_locations\u001b[0m\u001b[0;34m,\u001b[0m \u001b[0mbatch_face_locations\u001b[0m\u001b[0;34m,\u001b[0m \u001b[0mface_landmarks\u001b[0m\u001b[0;34m,\u001b[0m \u001b[0mface_encodings\u001b[0m\u001b[0;34m,\u001b[0m \u001b[0mcompare_faces\u001b[0m\u001b[0;34m,\u001b[0m \u001b[0mface_distance\u001b[0m\u001b[0;34m\u001b[0m\u001b[0;34m\u001b[0m\u001b[0m\n\u001b[0m",
            "\u001b[0;32m/usr/local/lib/python3.10/dist-packages/face_recognition/api.py\u001b[0m in \u001b[0;36m<module>\u001b[0;34m\u001b[0m\n\u001b[1;32m     24\u001b[0m \u001b[0;34m\u001b[0m\u001b[0m\n\u001b[1;32m     25\u001b[0m \u001b[0mcnn_face_detection_model\u001b[0m \u001b[0;34m=\u001b[0m \u001b[0mface_recognition_models\u001b[0m\u001b[0;34m.\u001b[0m\u001b[0mcnn_face_detector_model_location\u001b[0m\u001b[0;34m(\u001b[0m\u001b[0;34m)\u001b[0m\u001b[0;34m\u001b[0m\u001b[0;34m\u001b[0m\u001b[0m\n\u001b[0;32m---> 26\u001b[0;31m \u001b[0mcnn_face_detector\u001b[0m \u001b[0;34m=\u001b[0m \u001b[0mdlib\u001b[0m\u001b[0;34m.\u001b[0m\u001b[0mcnn_face_detection_model_v1\u001b[0m\u001b[0;34m(\u001b[0m\u001b[0mcnn_face_detection_model\u001b[0m\u001b[0;34m)\u001b[0m\u001b[0;34m\u001b[0m\u001b[0;34m\u001b[0m\u001b[0m\n\u001b[0m\u001b[1;32m     27\u001b[0m \u001b[0;34m\u001b[0m\u001b[0m\n\u001b[1;32m     28\u001b[0m \u001b[0mface_recognition_model\u001b[0m \u001b[0;34m=\u001b[0m \u001b[0mface_recognition_models\u001b[0m\u001b[0;34m.\u001b[0m\u001b[0mface_recognition_model_location\u001b[0m\u001b[0;34m(\u001b[0m\u001b[0;34m)\u001b[0m\u001b[0;34m\u001b[0m\u001b[0;34m\u001b[0m\u001b[0m\n",
            "\u001b[0;31mRuntimeError\u001b[0m: Error while calling cudaGetDevice(&the_device_id) in file /tmp/pip-install-bl_f6nbt/dlib_b7e3f77affac4712b41e4d328d8f290d/dlib/cuda/gpu_data.cpp:204. code: 35, reason: CUDA driver version is insufficient for CUDA runtime version"
          ]
        }
      ]
    },
    {
      "cell_type": "code",
      "source": [],
      "metadata": {
        "id": "jv1t6JuHNqCc"
      },
      "execution_count": null,
      "outputs": []
    }
  ]
}